---------------------------------------------------------------------------
MergeError                                Traceback (most recent call last)
Cell In[139], line 15
     12 df_dept['num_dpt'] = df_dept['num_dpt'].astype(str)
     13 df_dept['num_dpt'] = df_dept['num_dpt'].apply(lambda x: '0' + x if len(x) == 1 else x)
---> 15 df_ti_dept_sans_idf = pd.merge(df_ti_dept_sans_idf, df_dept, left_on='DEPT', right_on='num_dpt', how='inner')
     17 print(f"Lignes finales : {len(df_ti_dept_sans_idf)}")

File ~\AppData\Roaming\Python\Python311\site-packages\pandas\core\reshape\merge.py:184, in merge(left, right, how, on, left_on, right_on, left_index, right_index, sort, suffixes, copy, indicator, validate)
    169 else:
    170     op = _MergeOperation(
    171         left_df,
    172         right_df,
   (...)    182         validate=validate,
    183     )
--> 184     return op.get_result(copy=copy)

File ~\AppData\Roaming\Python\Python311\site-packages\pandas\core\reshape\merge.py:888, in _MergeOperation.get_result(self, copy)
    884     self.left, self.right = self._indicator_pre_merge(self.left, self.right)
    886 join_index, left_indexer, right_indexer = self._get_join_info()
--> 888 result = self._reindex_and_concat(
    889     join_index, left_indexer, right_indexer, copy=copy
    890 )
    891 result = result.__finalize__(self, method=self._merge_type)
    893 if self.indicator:
...
   2759         f"not allowed.",
   2760     )
   2762 return llabels, rlabels

MergeError: Passing 'suffixes' which cause duplicate columns {'1999_x', 
